<?xml version="1.0" ?>
<mujoco>
  <compiler angle="radian" autolimits="true"/>
  <option gravity="0 0 -9.81" timestep="0.01"/>
  <visual>
    <headlight diffuse="0.6 0.6 0.6" ambient="0.3 0.3 0.3" specular="0 0 0"/>
  </visual>
  <asset>
    <texture name="grid" type="2d" builtin="checker" width="512" height="512" rgb1="0.1 0.2 0.3" rgb2="0.2 0.3 0.4"/>
    <material name="grid" texture="grid" texrepeat="1 1" texuniform="true" reflectance="0.2"/>
  </asset>
  <worldbody>
    <geom name="floor" type="plane" size="10 10 0.1" material="grid" pos="0 0 0"/>
    <light name="spotlight" directional="true" diffuse="0.8 0.8 0.8" specular="0.2 0.2 0.2" pos="0 -2 4" dir="0 1 -1"/>
    <body name="Armature_body">
      <geom type="capsule" size="0.02" fromto="0 0 0 -0.011092236824333667 0.0 -0.003149164840579033" rgba="0.9 0.9 0.9 0.8"/>
      <joint name="Armature" type="free"/>
      <body name="Root_body" pos="-0.012324707582592964 0.0 -0.0034990720450878143">
        <geom type="capsule" size="0.02" fromto="0 0 0 -1.5467069225394426e-08 0.0 0.37959182560443877" rgba="0.9 0.9 0.9 0.8"/>
        <joint name="Root" type="ball"/>
        <body name="Hip_body" pos="-1.7185632472660473e-08 0.0 0.4217686951160431">
          <geom type="sphere" size="0.02" rgba="0.8 0.8 0.8 0.8"/>
          <joint name="Hip" type="ball"/>
          <body name="Pelvis_body" pos="0.0 0.001 0.0">
            <geom type="capsule" size="0.02" fromto="0 0 0 -0.06599959507584573 -8.671435716678388e-05 0.0014363062684424222" rgba="0.9 0.9 0.9 0.8"/>
            <joint name="Pelvis" type="ball"/>
            <body name="L_Thigh_body" pos="-0.07333288341760635 -9.634928574087098e-05 0.0015958958538249135">
              <geom type="capsule" size="0.02" fromto="0 0 0 -2.3081155086401852e-05 0.15378540605306626 -1.2491035022321739e-06" rgba="0.9 0.9 0.9 0.8"/>
              <joint name="L_Thigh" type="ball"/>
              <body name="L_Calf_body" pos="-2.5645727873779833e-05 0.17087267339229584 -1.387892780257971e-06">
                <geom type="capsule" size="0.02" fromto="0 0 0 -4.185712896287441e-07 0.16974603831768037 4.216037377773319e-05" rgba="0.9 0.9 0.9 0.8"/>
                <joint name="L_Calf" type="ball"/>
                <body name="L_Foot_body" pos="-4.650792106986046e-07 0.18860670924186707 4.684485975303687e-05">
                  <geom type="sphere" size="0.015" rgba="1 0.5 0.5 0.8"/>
                  <joint name="L_Foot" type="ball"/>
                </body>
                <body name="L_CalfTwist01_body" pos="-6.2427716329693794e-09 -0.00011017103679478168 -8.355964808970384e-09">
                  <geom type="capsule" size="0.02" fromto="0 0 0 2.35741026699543e-10 0.07082881182432176 -1.1125791488098002e-08" rgba="0.9 0.9 0.9 0.8"/>
                  <joint name="L_CalfTwist01" type="ball"/>
                  <body name="L_CalfTwist02_body" pos="2.6193447411060333e-10 0.07869867980480194 -1.2361990542331114e-08">
                    <geom type="sphere" size="0.015" rgba="1 0.5 0.5 0.8"/>
                    <joint name="L_CalfTwist02" type="ball"/>
                  </body>
                </body>
              </body>
              <body name="L_ThighTwist01_body" pos="-2.045271685346961e-08 -8.537725079804659e-05 7.491512299395708e-09">
                <geom type="capsule" size="0.02" fromto="0 0 0 3.621244104579091e-09 0.07688540071249009 2.1851704445907673e-09" rgba="0.9 0.9 0.9 0.8"/>
                <joint name="L_ThighTwist01" type="ball"/>
                <body name="L_ThighTwist02_body" pos="4.0236045606434345e-09 0.08542822301387787 2.427967160656408e-09">
                  <geom type="sphere" size="0.015" rgba="1 0.5 0.5 0.8"/>
                  <joint name="L_ThighTwist02" type="ball"/>
                </body>
              </body>
            </body>
            <body name="R_Thigh_body" pos="0.07334408164024353 -0.00023531090118922293 -0.0015533219557255507">
              <geom type="capsule" size="0.02" fromto="0 0 0 -9.856325355883656e-09 -7.380791575997137e-05 8.429736908510677e-10" rgba="0.9 0.9 0.9 0.8"/>
              <joint name="R_Thigh" type="ball"/>
              <body name="R_ThighTwist01_body" pos="-1.0951472617648506e-08 -8.200879528885707e-05 9.36637434278964e-10">
                <geom type="capsule" size="0.02" fromto="0 0 0 -6.0919733257946975e-09 0.0737862691283226 -1.119616399591905e-08" rgba="0.9 0.9 0.9 0.8"/>
                <joint name="R_ThighTwist01" type="ball"/>
                <body name="R_ThighTwist02_body" pos="-6.768859250882997e-09 0.081984743475914 -1.2440182217687834e-08">
                  <geom type="sphere" size="0.015" rgba="1 0.5 0.5 0.8"/>
                  <joint name="R_ThighTwist02" type="ball"/>
                </body>
              </body>
              <body name="R_Calf_body" pos="1.0887441931117792e-05 0.1639886349439621 2.2789558897784445e-06">
                <geom type="capsule" size="0.02" fromto="0 0 0 2.5634217308834196e-07 0.16473300307989122 4.088786336069461e-05" rgba="0.9 0.9 0.9 0.8"/>
                <joint name="R_Calf" type="ball"/>
                <body name="R_Foot_body" pos="2.848246367648244e-07 0.183036670088768 4.543095928966068e-05">
                  <geom type="sphere" size="0.015" rgba="1 0.5 0.5 0.8"/>
                  <joint name="R_Foot" type="ball"/>
                </body>
                <body name="R_CalfTwist01_body" pos="1.2660166248679161e-08 -0.00010692840442061424 -2.861646919427585e-09">
                  <geom type="capsule" size="0.02" fromto="0 0 0 -1.7025740817189218e-10 0.06873717829585076 -4.236147432834514e-10" rgba="0.9 0.9 0.9 0.8"/>
                  <joint name="R_CalfTwist01" type="ball"/>
                  <body name="R_CalfTwist02_body" pos="-1.8917489796876907e-10 0.07637464255094528 -4.706830480927238e-10">
                    <geom type="sphere" size="0.015" rgba="1 0.5 0.5 0.8"/>
                    <joint name="R_CalfTwist02" type="ball"/>
                  </body>
                </body>
              </body>
            </body>
          </body>
          <body name="Waist_body" pos="2.4497974663972855e-05 4.139832526561804e-05 2.095615491271019e-05">
            <geom type="capsule" size="0.02" fromto="0 0 0 -3.313433527551979e-10 0.04724057056009769 1.9737625533977622e-09" rgba="0.9 0.9 0.9 0.8"/>
            <joint name="Waist" type="ball"/>
            <body name="Spine01_body" pos="-3.6815928083910876e-10 0.052489522844552994 2.193069503775291e-09">
              <geom type="capsule" size="0.02" fromto="0 0 0 1.2752399136672922e-11 0.09437498599290849 -2.214463812322265e-09" rgba="0.9 0.9 0.9 0.8"/>
              <joint name="Spine01" type="ball"/>
              <body name="Spine02_body" pos="1.4169332374081023e-11 0.10486109554767609 -2.4605153470247387e-09">
                <geom type="capsule" size="0.02" fromto="0 0 0 3.245883561930896e-11 0.08253971859812737 -1.3644948171354089e-09" rgba="0.9 0.9 0.9 0.8"/>
                <joint name="Spine02" type="ball"/>
                <body name="NeckTwist01_body" pos="3.6065372910343285e-11 0.09171079844236374 -1.5161053523726764e-09">
                  <geom type="capsule" size="0.02" fromto="0 0 0 -1.2868546228617107e-10 0.033894733339548115 6.07799710561352e-10" rgba="0.9 0.9 0.9 0.8"/>
                  <joint name="NeckTwist01" type="ball"/>
                  <body name="NeckTwist02_body" pos="-1.429838469846345e-10 0.03766081482172012 6.753330117348355e-10">
                    <geom type="capsule" size="0.02" fromto="0 0 0 1.9984833787844992e-10 0.02215242125093937 2.8964796561226083e-09" rgba="0.9 0.9 0.9 0.8"/>
                    <joint name="NeckTwist02" type="ball"/>
                    <body name="Head_body" pos="2.2205370875383323e-10 0.024613801389932632 3.21831072902512e-09">
                      <geom type="sphere" size="0.015" rgba="1 0.5 0.5 0.8"/>
                      <joint name="Head" type="ball"/>
                    </body>
                  </body>
                </body>
                <body name="L_Clavicle_body" pos="-0.019999975338578224 0.0916731134057045 5.78786263361053e-09">
                  <geom type="capsule" size="0.02" fromto="0 0 0 1.4021742026670836e-05 0.07566317841410637 -3.5889381706510903e-06" rgba="0.9 0.9 0.9 0.8"/>
                  <joint name="L_Clavicle" type="ball"/>
                  <body name="L_Upperarm_body" pos="1.5579713362967595e-05 0.08407019823789597 -3.9877090785012115e-06">
                    <geom type="capsule" size="0.02" fromto="0 0 0 -1.8502658349461854e-06 0.08682262971997261 4.6091185140539895e-06" rgba="0.9 0.9 0.9 0.8"/>
                    <joint name="L_Upperarm" type="ball"/>
                    <body name="L_Forearm_body" pos="-2.0558509277179837e-06 0.09646958857774734 5.121242793393321e-06">
                      <geom type="capsule" size="0.02" fromto="0 0 0 1.5501841410525686e-08 -4.023360670544207e-05 1.7217011816228478e-09" rgba="0.9 0.9 0.9 0.8"/>
                      <joint name="L_Forearm" type="ball"/>
                      <body name="L_ForearmTwist01_body" pos="1.7224268233917428e-08 -4.470400745049119e-05 1.9130013129142753e-09">
                        <geom type="capsule" size="0.02" fromto="0 0 0 1.2409298588700324e-09 0.04025212526321411 -3.459760478108365e-10" rgba="0.9 0.9 0.9 0.8"/>
                        <joint name="L_ForearmTwist01" type="ball"/>
                        <body name="L_ForearmTwist02_body" pos="1.378810954300036e-09 0.04472458362579346 -3.844178309009294e-10">
                          <geom type="sphere" size="0.015" rgba="1 0.5 0.5 0.8"/>
                          <joint name="L_ForearmTwist02" type="ball"/>
                        </body>
                      </body>
                      <body name="L_Hand_body" pos="1.7111497996324943e-08 0.08937765657901764 2.378655494794657e-09">
                        <geom type="sphere" size="0.015" rgba="1 0.5 0.5 0.8"/>
                        <joint name="L_Hand" type="ball"/>
                      </body>
                    </body>
                    <body name="L_UpperarmTwist01_body" pos="1.2324198905844241e-07 -4.826957592740655e-05 2.836770818248624e-10">
                      <geom type="capsule" size="0.02" fromto="0 0 0 6.483041943283752e-08 0.04341455027461052 2.1934454252914293e-10" rgba="0.9 0.9 0.9 0.8"/>
                      <joint name="L_UpperarmTwist01" type="ball"/>
                      <body name="L_UpperarmTwist02_body" pos="7.203379936981946e-08 0.04823838919401169 2.4371615836571436e-10">
                        <geom type="sphere" size="0.015" rgba="1 0.5 0.5 0.8"/>
                        <joint name="L_UpperarmTwist02" type="ball"/>
                      </body>
                    </body>
                  </body>
                </body>
                <body name="R_Clavicle_body" pos="0.020000014454126358 0.0916731059551239 -5.094797028704079e-09">
                  <geom type="capsule" size="0.02" fromto="0 0 0 -2.8797992854379117e-05 0.07663030922412872 2.4921593876570115e-06" rgba="0.9 0.9 0.9 0.8"/>
                  <joint name="R_Clavicle" type="ball"/>
                  <body name="R_Upperarm_body" pos="-3.199776983819902e-05 0.08514478802680969 2.7690659862855682e-06">
                    <geom type="capsule" size="0.02" fromto="0 0 0 5.465917638503015e-08 -4.450241176527925e-05 -4.870088332609158e-10" rgba="0.9 0.9 0.9 0.8"/>
                    <joint name="R_Upperarm" type="ball"/>
                    <body name="R_UpperarmTwist01_body" pos="6.073241820558906e-08 -4.944712418364361e-05 -5.411209258454619e-10">
                      <geom type="capsule" size="0.02" fromto="0 0 0 -6.823147487011738e-08 0.04450485482811928 1.496447765703124e-09" rgba="0.9 0.9 0.9 0.8"/>
                      <joint name="R_UpperarmTwist01" type="ball"/>
                      <body name="R_UpperarmTwist02_body" pos="-7.581274985568598e-08 0.04944983869791031 1.6627197396701376e-09">
                        <geom type="sphere" size="0.015" rgba="1 0.5 0.5 0.8"/>
                        <joint name="R_UpperarmTwist02" type="ball"/>
                      </body>
                    </body>
                    <body name="R_Forearm_body" pos="8.797584087005816e-06 0.09889685362577438 1.5775609426782466e-05">
                      <geom type="capsule" size="0.02" fromto="0 0 0 -5.051165246072742e-08 -4.3971804552711545e-05 6.934298735217226e-09" rgba="0.9 0.9 0.9 0.8"/>
                      <joint name="R_Forearm" type="ball"/>
                      <body name="R_ForearmTwist01_body" pos="-5.612405828969713e-08 -4.885756061412394e-05 7.704776372463584e-09">
                        <geom type="capsule" size="0.02" fromto="0 0 0 -5.590396625620997e-08 0.043947532027959826 4.340713388728545e-09" rgba="0.9 0.9 0.9 0.8"/>
                        <joint name="R_ForearmTwist01" type="ball"/>
                        <body name="R_ForearmTwist02_body" pos="-6.211551806245552e-08 0.04883059114217758 4.8230148763650504e-09">
                          <geom type="sphere" size="0.015" rgba="1 0.5 0.5 0.8"/>
                          <joint name="R_ForearmTwist02" type="ball"/>
                        </body>
                      </body>
                      <body name="R_Hand_body" pos="6.445776534746983e-08 0.09758304059505463 -1.608449151646596e-09">
                        <geom type="sphere" size="0.015" rgba="1 0.5 0.5 0.8"/>
                        <joint name="R_Hand" type="ball"/>
                      </body>
                    </body>
                  </body>
                </body>
              </body>
            </body>
          </body>
        </body>
      </body>
    </body>
  </worldbody>
  <actuator>
    <motor name="Armature_motor" joint="Armature" gear="250" ctrllimited="true" ctrlrange="-1 1"/>
    <motor name="Head_motor" joint="Head" gear="100" ctrllimited="true" ctrlrange="-1 1"/>
    <motor name="Hip_motor" joint="Hip" gear="100" ctrllimited="true" ctrlrange="-1 1"/>
    <motor name="L_Calf_motor" joint="L_Calf" gear="100" ctrllimited="true" ctrlrange="-1 1"/>
    <motor name="L_CalfTwist01_motor" joint="L_CalfTwist01" gear="100" ctrllimited="true" ctrlrange="-1 1"/>
    <motor name="L_CalfTwist02_motor" joint="L_CalfTwist02" gear="100" ctrllimited="true" ctrlrange="-1 1"/>
    <motor name="L_Clavicle_motor" joint="L_Clavicle" gear="100" ctrllimited="true" ctrlrange="-1 1"/>
    <motor name="L_Foot_motor" joint="L_Foot" gear="100" ctrllimited="true" ctrlrange="-1 1"/>
    <motor name="L_Forearm_motor" joint="L_Forearm" gear="100" ctrllimited="true" ctrlrange="-1 1"/>
    <motor name="L_ForearmTwist01_motor" joint="L_ForearmTwist01" gear="100" ctrllimited="true" ctrlrange="-1 1"/>
    <motor name="L_ForearmTwist02_motor" joint="L_ForearmTwist02" gear="100" ctrllimited="true" ctrlrange="-1 1"/>
    <motor name="L_Hand_motor" joint="L_Hand" gear="100" ctrllimited="true" ctrlrange="-1 1"/>
    <motor name="L_Thigh_motor" joint="L_Thigh" gear="100" ctrllimited="true" ctrlrange="-1 1"/>
    <motor name="L_ThighTwist01_motor" joint="L_ThighTwist01" gear="100" ctrllimited="true" ctrlrange="-1 1"/>
    <motor name="L_ThighTwist02_motor" joint="L_ThighTwist02" gear="100" ctrllimited="true" ctrlrange="-1 1"/>
    <motor name="L_Upperarm_motor" joint="L_Upperarm" gear="100" ctrllimited="true" ctrlrange="-1 1"/>
    <motor name="L_UpperarmTwist01_motor" joint="L_UpperarmTwist01" gear="100" ctrllimited="true" ctrlrange="-1 1"/>
    <motor name="L_UpperarmTwist02_motor" joint="L_UpperarmTwist02" gear="100" ctrllimited="true" ctrlrange="-1 1"/>
    <motor name="NeckTwist01_motor" joint="NeckTwist01" gear="100" ctrllimited="true" ctrlrange="-1 1"/>
    <motor name="NeckTwist02_motor" joint="NeckTwist02" gear="100" ctrllimited="true" ctrlrange="-1 1"/>
    <motor name="Pelvis_motor" joint="Pelvis" gear="100" ctrllimited="true" ctrlrange="-1 1"/>
    <motor name="R_Calf_motor" joint="R_Calf" gear="100" ctrllimited="true" ctrlrange="-1 1"/>
    <motor name="R_CalfTwist01_motor" joint="R_CalfTwist01" gear="100" ctrllimited="true" ctrlrange="-1 1"/>
    <motor name="R_CalfTwist02_motor" joint="R_CalfTwist02" gear="100" ctrllimited="true" ctrlrange="-1 1"/>
    <motor name="R_Clavicle_motor" joint="R_Clavicle" gear="100" ctrllimited="true" ctrlrange="-1 1"/>
    <motor name="R_Foot_motor" joint="R_Foot" gear="100" ctrllimited="true" ctrlrange="-1 1"/>
    <motor name="R_Forearm_motor" joint="R_Forearm" gear="100" ctrllimited="true" ctrlrange="-1 1"/>
    <motor name="R_ForearmTwist01_motor" joint="R_ForearmTwist01" gear="100" ctrllimited="true" ctrlrange="-1 1"/>
    <motor name="R_ForearmTwist02_motor" joint="R_ForearmTwist02" gear="100" ctrllimited="true" ctrlrange="-1 1"/>
    <motor name="R_Hand_motor" joint="R_Hand" gear="100" ctrllimited="true" ctrlrange="-1 1"/>
    <motor name="R_Thigh_motor" joint="R_Thigh" gear="100" ctrllimited="true" ctrlrange="-1 1"/>
    <motor name="R_ThighTwist01_motor" joint="R_ThighTwist01" gear="100" ctrllimited="true" ctrlrange="-1 1"/>
    <motor name="R_ThighTwist02_motor" joint="R_ThighTwist02" gear="100" ctrllimited="true" ctrlrange="-1 1"/>
    <motor name="R_Upperarm_motor" joint="R_Upperarm" gear="100" ctrllimited="true" ctrlrange="-1 1"/>
    <motor name="R_UpperarmTwist01_motor" joint="R_UpperarmTwist01" gear="100" ctrllimited="true" ctrlrange="-1 1"/>
    <motor name="R_UpperarmTwist02_motor" joint="R_UpperarmTwist02" gear="100" ctrllimited="true" ctrlrange="-1 1"/>
    <motor name="Root_motor" joint="Root" gear="100" ctrllimited="true" ctrlrange="-1 1"/>
    <motor name="Spine01_motor" joint="Spine01" gear="100" ctrllimited="true" ctrlrange="-1 1"/>
    <motor name="Spine02_motor" joint="Spine02" gear="100" ctrllimited="true" ctrlrange="-1 1"/>
    <motor name="Waist_motor" joint="Waist" gear="100" ctrllimited="true" ctrlrange="-1 1"/>
  </actuator>
</mujoco>
